<sdf version='1.7'>
  <model name='champ'>
    <link name='base_link'>
      <inertial>
        <pose>0.020235 0 0.005403 0 -0 0</pose>
        <mass>2.471</mass>
        <inertia>
          <ixx>0.021707</ixx>
          <ixy>0</ixy>
          <ixz>0.00402013</ixz>
          <iyy>0.0602953</iyy>
          <iyz>0</iyz>
          <izz>0.0679244</izz>
        </inertia>
      </inertial>
      <collision name='base_link_collision'>
        <pose>0 0 0 0 -0 0</pose>
        <geometry>
          <mesh>
            <scale>0.001 0.001 0.001</scale>
            <uri>file:///root/ros2_ws/install/champ_description/share/champ_description/meshes/base_simple.stl</uri>
          </mesh>
        </geometry>
        <surface>
          <contact>
            <ode/>
          </contact>
          <friction>
            <ode/>
          </friction>
        </surface>
      </collision>
      <collision name='base_link_fixed_joint_lump__camera_link_collision_1'>
        <pose>0.25 0 -0.075 0 -0 0</pose>
        <geometry>
          <mesh>
            <scale>1 1 1</scale>
            <uri>file:///root/ros2_ws/install/champ_description/share/champ_description/meshes/asus_camera_simple.dae</uri>
          </mesh>
        </geometry>
      </collision>
      <collision name='base_link_fixed_joint_lump__hokuyo_frame_collision_2'>
        <pose>0 0 0.0935 0 -0 0</pose>
        <geometry>
          <box>
            <size>0.058 0.058 0.087</size>
          </box>
        </geometry>
        <surface>
          <contact>
            <ode/>
          </contact>
          <friction>
            <ode/>
          </friction>
        </surface>
      </collision>
      <visual name='base_link_visual'>
        <pose>0 0 0 0 -0 0</pose>
        <geometry>
          <mesh>
            <scale>0.001 0.001 0.001</scale>
            <uri>file:///root/ros2_ws/install/champ_description/share/champ_description/meshes/base_simple.stl</uri>
          </mesh>
        </geometry>
        <material>
          <script>
            <name>Gazebo/FlatBlack</name>
            <uri>file://media/materials/scripts/gazebo.material</uri>
          </script>
        </material>
      </visual>
      <visual name='base_link_fixed_joint_lump__camera_link_visual_1'>
        <pose>0.25 0 -0.075 0 -0 0</pose>
        <geometry>
          <mesh>
            <scale>1 1 1</scale>
            <uri>file:///root/ros2_ws/install/champ_description/share/champ_description/meshes/asus_camera_simple.dae</uri>
          </mesh>
        </geometry>
      </visual>
      <visual name='base_link_fixed_joint_lump__hokuyo_frame_visual_2'>
        <pose>0 0 0.105 0 -0 0</pose>
        <geometry>
          <mesh>
            <scale>1 1 1</scale>
            <uri>file:///root/ros2_ws/install/champ_description/share/champ_description/meshes/hokuyo_utm_30lx.dae</uri>
          </mesh>
        </geometry>
      </visual>
      <sensor name='camera' type='depth'>
        <update_rate>20</update_rate>
        <camera name='camera_depth_frame_camera'>
          <horizontal_fov>1.09607</horizontal_fov>
          <image>
            <format>R8G8B8</format>
            <width>640</width>
            <height>480</height>
          </image>
          <clip>
            <near>0.5</near>
            <far>9</far>
          </clip>
        </camera>
        <always_on>1</always_on>
        <update_rate>30</update_rate>
        <pose>0.25 0.049 -0.075 0 -0 0</pose>
      </sensor>
      <sensor name='hokuyo' type='ray'>
        <always_on>1</always_on>
        <update_rate>30</update_rate>
        <visualize>0</visualize>
        <ray>
          <scan>
            <horizontal>
              <samples>1040</samples>
              <resolution>1</resolution>
              <min_angle>2.26893</min_angle>
              <max_angle>-2.26893</max_angle>
            </horizontal>
          </scan>
          <range>
            <min>0.2</min>
            <max>30</max>
            <resolution>0.01</resolution>
          </range>
          <noise>
            <type>gaussian</type>
            <mean>0</mean>
            <stddev>0.004</stddev>
          </noise>
        </ray>
        <pose>0 0 0.105 0 -0 0</pose>
      </sensor>
      <sensor name='imu_controller' type='imu'>
        <always_on>1</always_on>
        <update_rate>50</update_rate>
        <pose>0 0 0 0 -0 0</pose>
      </sensor>
    </link>
    <joint name='lf_hip_joint' type='revolute'>
      <pose relative_to='base_link'>0.175 0.105 0 0 -0 0</pose>
      <parent>base_link</parent>
      <child>lf_hip_link</child>
      <axis>
        <xyz>1 0 0</xyz>
        <limit>
          <lower>-3.14159</lower>
          <upper>3.14159</upper>
          <effort>25</effort>
          <velocity>1.5</velocity>
        </limit>
        <dynamics>
          <spring_reference>0</spring_reference>
          <spring_stiffness>0</spring_stiffness>
        </dynamics>
      </axis>
    </joint>
    <link name='lf_hip_link'>
      <pose relative_to='lf_hip_joint'>0 0 0 0 -0 0</pose>
      <inertial>
        <pose>0 0 0 0 -0 0</pose>
        <mass>0.25</mass>
        <inertia>
          <ixx>0.000485417</ixx>
          <ixy>0</ixy>
          <ixz>0</ixz>
          <iyy>0.000613417</iyy>
          <iyz>0</iyz>
          <izz>0.000394667</izz>
        </inertia>
      </inertial>
      <collision name='lf_hip_link_collision'>
        <pose>0 0 0 0 -0 0</pose>
        <geometry>
          <mesh>
            <scale>0.001 0.001 0.001</scale>
            <uri>file:///root/ros2_ws/install/champ_description/share/champ_description/meshes/hip.stl</uri>
          </mesh>
        </geometry>
        <surface>
          <contact>
            <ode/>
          </contact>
          <friction>
            <ode/>
          </friction>
        </surface>
      </collision>
      <visual name='lf_hip_link_visual'>
        <pose>0 0 0 0 -0 0</pose>
        <geometry>
          <mesh>
            <scale>0.001 0.001 0.001</scale>
            <uri>file:///root/ros2_ws/install/champ_description/share/champ_description/meshes/hip.stl</uri>
          </mesh>
        </geometry>
        <material>
          <script>
            <name>Gazebo/FlatBlack</name>
            <uri>file://media/materials/scripts/gazebo.material</uri>
          </script>
        </material>
      </visual>
    </link>
    <joint name='lf_upper_leg_joint' type='revolute'>
      <pose relative_to='lf_hip_link'>0 0.06 0 0 -0 0</pose>
      <parent>lf_hip_link</parent>
      <child>lf_upper_leg_link</child>
      <axis>
        <xyz>0 1 0</xyz>
        <limit>
          <lower>-3.14159</lower>
          <upper>3.14159</upper>
          <effort>25</effort>
          <velocity>1.5</velocity>
        </limit>
        <dynamics>
          <spring_reference>0</spring_reference>
          <spring_stiffness>0</spring_stiffness>
        </dynamics>
      </axis>
    </joint>
    <link name='lf_upper_leg_link'>
      <pose relative_to='lf_upper_leg_joint'>0 0 0 0 -0 0</pose>
      <inertial>
        <pose>0 0 -0.0705 0 -0 0</pose>
        <mass>0.125</mass>
        <inertia>
          <ixx>0.000387398</ixx>
          <ixy>0</ixy>
          <ixz>0</ixz>
          <iyy>0.000404065</iyy>
          <iyz>0</iyz>
          <izz>3.54167e-05</izz>
        </inertia>
      </inertial>
      <collision name='lf_upper_leg_link_collision'>
        <pose>0 0 0 0 -0 0</pose>
        <geometry>
          <mesh>
            <scale>0.001 0.001 0.001</scale>
            <uri>file:///root/ros2_ws/install/champ_description/share/champ_description/meshes/upper_leg_simple.stl</uri>
          </mesh>
        </geometry>
        <surface>
          <contact>
            <ode/>
          </contact>
          <friction>
            <ode/>
          </friction>
        </surface>
      </collision>
      <visual name='lf_upper_leg_link_visual'>
        <pose>0 0 0 0 -0 0</pose>
        <geometry>
          <mesh>
            <scale>0.001 0.001 0.001</scale>
            <uri>file:///root/ros2_ws/install/champ_description/share/champ_description/meshes/upper_leg_simple.stl</uri>
          </mesh>
        </geometry>
        <material>
          <script>
            <name>Gazebo/FlatBlack</name>
            <uri>file://media/materials/scripts/gazebo.material</uri>
          </script>
        </material>
      </visual>
    </link>
    <joint name='lf_lower_leg_joint' type='revolute'>
      <pose relative_to='lf_upper_leg_link'>0 0 -0.141 0 -0 0</pose>
      <parent>lf_upper_leg_link</parent>
      <child>lf_lower_leg_link</child>
      <axis>
        <xyz>0 1 0</xyz>
        <limit>
          <lower>-3.14159</lower>
          <upper>3.14159</upper>
          <effort>25</effort>
          <velocity>1.5</velocity>
        </limit>
        <dynamics>
          <spring_reference>0</spring_reference>
          <spring_stiffness>0</spring_stiffness>
        </dynamics>
      </axis>
    </joint>
    <link name='lf_lower_leg_link'>
      <pose relative_to='lf_lower_leg_joint'>0 0 0 0 -0 0</pose>
      <inertial>
        <pose>0 0 -0.063 0 -0 0</pose>
        <mass>0.125</mass>
        <inertia>
          <ixx>0.000258542</ixx>
          <ixy>0</ixy>
          <ixz>0</ixz>
          <iyy>0.000269344</iyy>
          <iyz>0</iyz>
          <izz>2.08854e-05</izz>
        </inertia>
      </inertial>
      <collision name='lf_lower_leg_link_collision'>
        <pose>0 0 0 0 -0 0</pose>
        <geometry>
          <mesh>
            <scale>0.001 0.001 0.001</scale>
            <uri>file:///root/ros2_ws/install/champ_description/share/champ_description/meshes/lower_leg_simple.stl</uri>
          </mesh>
        </geometry>
        <surface>
          <contact>
            <ode>
              <kp>1e+10</kp>
              <kd>100</kd>
              <min_depth>0.05</min_depth>
            </ode>
          </contact>
          <friction>
            <ode>
              <mu>0.8</mu>
              <mu2>0.8</mu2>
            </ode>
          </friction>
        </surface>
      </collision>
      <visual name='lf_lower_leg_link_visual'>
        <pose>0 0 0 0 -0 0</pose>
        <geometry>
          <mesh>
            <scale>0.001 0.001 0.001</scale>
            <uri>file:///root/ros2_ws/install/champ_description/share/champ_description/meshes/lower_leg_simple.stl</uri>
          </mesh>
        </geometry>
        <material>
          <script>
            <name>Gazebo/FlatBlack</name>
            <uri>file://media/materials/scripts/gazebo.material</uri>
          </script>
        </material>
      </visual>
    </link>
    <joint name='lh_hip_joint' type='revolute'>
      <pose relative_to='base_link'>-0.175 0.105 0 0 -0 0</pose>
      <parent>base_link</parent>
      <child>lh_hip_link</child>
      <axis>
        <xyz>1 0 0</xyz>
        <limit>
          <lower>-3.14159</lower>
          <upper>3.14159</upper>
          <effort>25</effort>
          <velocity>1.5</velocity>
        </limit>
        <dynamics>
          <spring_reference>0</spring_reference>
          <spring_stiffness>0</spring_stiffness>
        </dynamics>
      </axis>
    </joint>
    <link name='lh_hip_link'>
      <pose relative_to='lh_hip_joint'>0 0 0 0 -0 0</pose>
      <inertial>
        <pose>0 0 0 0 -0 0</pose>
        <mass>0.25</mass>
        <inertia>
          <ixx>0.000485417</ixx>
          <ixy>0</ixy>
          <ixz>0</ixz>
          <iyy>0.000613417</iyy>
          <iyz>0</iyz>
          <izz>0.000394667</izz>
        </inertia>
      </inertial>
      <collision name='lh_hip_link_collision'>
        <pose>0 0 0 0 -0 0</pose>
        <geometry>
          <mesh>
            <scale>0.001 0.001 0.001</scale>
            <uri>file:///root/ros2_ws/install/champ_description/share/champ_description/meshes/hip.stl</uri>
          </mesh>
        </geometry>
        <surface>
          <contact>
            <ode/>
          </contact>
          <friction>
            <ode/>
          </friction>
        </surface>
      </collision>
      <visual name='lh_hip_link_visual'>
        <pose>0 0 0 0 -0 0</pose>
        <geometry>
          <mesh>
            <scale>0.001 0.001 0.001</scale>
            <uri>file:///root/ros2_ws/install/champ_description/share/champ_description/meshes/hip.stl</uri>
          </mesh>
        </geometry>
        <material>
          <script>
            <name>Gazebo/FlatBlack</name>
            <uri>file://media/materials/scripts/gazebo.material</uri>
          </script>
        </material>
      </visual>
    </link>
    <joint name='lh_upper_leg_joint' type='revolute'>
      <pose relative_to='lh_hip_link'>0 0.06 0 0 -0 0</pose>
      <parent>lh_hip_link</parent>
      <child>lh_upper_leg_link</child>
      <axis>
        <xyz>0 1 0</xyz>
        <limit>
          <lower>-3.14159</lower>
          <upper>3.14159</upper>
          <effort>25</effort>
          <velocity>1.5</velocity>
        </limit>
        <dynamics>
          <spring_reference>0</spring_reference>
          <spring_stiffness>0</spring_stiffness>
        </dynamics>
      </axis>
    </joint>
    <link name='lh_upper_leg_link'>
      <pose relative_to='lh_upper_leg_joint'>0 0 0 0 -0 0</pose>
      <inertial>
        <pose>0 0 -0.0705 0 -0 0</pose>
        <mass>0.125</mass>
        <inertia>
          <ixx>0.000387398</ixx>
          <ixy>0</ixy>
          <ixz>0</ixz>
          <iyy>0.000404065</iyy>
          <iyz>0</iyz>
          <izz>3.54167e-05</izz>
        </inertia>
      </inertial>
      <collision name='lh_upper_leg_link_collision'>
        <pose>0 0 0 0 -0 0</pose>
        <geometry>
          <mesh>
            <scale>0.001 0.001 0.001</scale>
            <uri>file:///root/ros2_ws/install/champ_description/share/champ_description/meshes/upper_leg_simple.stl</uri>
          </mesh>
        </geometry>
        <surface>
          <contact>
            <ode/>
          </contact>
          <friction>
            <ode/>
          </friction>
        </surface>
      </collision>
      <visual name='lh_upper_leg_link_visual'>
        <pose>0 0 0 0 -0 0</pose>
        <geometry>
          <mesh>
            <scale>0.001 0.001 0.001</scale>
            <uri>file:///root/ros2_ws/install/champ_description/share/champ_description/meshes/upper_leg_simple.stl</uri>
          </mesh>
        </geometry>
        <material>
          <script>
            <name>Gazebo/FlatBlack</name>
            <uri>file://media/materials/scripts/gazebo.material</uri>
          </script>
        </material>
      </visual>
    </link>
    <joint name='lh_lower_leg_joint' type='revolute'>
      <pose relative_to='lh_upper_leg_link'>0 0 -0.141 0 -0 0</pose>
      <parent>lh_upper_leg_link</parent>
      <child>lh_lower_leg_link</child>
      <axis>
        <xyz>0 1 0</xyz>
        <limit>
          <lower>-3.14159</lower>
          <upper>3.14159</upper>
          <effort>25</effort>
          <velocity>1.5</velocity>
        </limit>
        <dynamics>
          <spring_reference>0</spring_reference>
          <spring_stiffness>0</spring_stiffness>
        </dynamics>
      </axis>
    </joint>
    <link name='lh_lower_leg_link'>
      <pose relative_to='lh_lower_leg_joint'>0 0 0 0 -0 0</pose>
      <inertial>
        <pose>0 0 -0.063 0 -0 0</pose>
        <mass>0.125</mass>
        <inertia>
          <ixx>0.000258542</ixx>
          <ixy>0</ixy>
          <ixz>0</ixz>
          <iyy>0.000269344</iyy>
          <iyz>0</iyz>
          <izz>2.08854e-05</izz>
        </inertia>
      </inertial>
      <collision name='lh_lower_leg_link_collision'>
        <pose>0 0 0 0 -0 0</pose>
        <geometry>
          <mesh>
            <scale>0.001 0.001 0.001</scale>
            <uri>file:///root/ros2_ws/install/champ_description/share/champ_description/meshes/lower_leg_simple.stl</uri>
          </mesh>
        </geometry>
        <surface>
          <contact>
            <ode>
              <kp>1e+10</kp>
              <kd>100</kd>
              <min_depth>0.05</min_depth>
            </ode>
          </contact>
          <friction>
            <ode>
              <mu>0.8</mu>
              <mu2>0.8</mu2>
            </ode>
          </friction>
        </surface>
      </collision>
      <visual name='lh_lower_leg_link_visual'>
        <pose>0 0 0 0 -0 0</pose>
        <geometry>
          <mesh>
            <scale>0.001 0.001 0.001</scale>
            <uri>file:///root/ros2_ws/install/champ_description/share/champ_description/meshes/lower_leg_simple.stl</uri>
          </mesh>
        </geometry>
        <material>
          <script>
            <name>Gazebo/FlatBlack</name>
            <uri>file://media/materials/scripts/gazebo.material</uri>
          </script>
        </material>
      </visual>
    </link>
    <joint name='rf_hip_joint' type='revolute'>
      <pose relative_to='base_link'>0.175 -0.105 0 0 -0 0</pose>
      <parent>base_link</parent>
      <child>rf_hip_link</child>
      <axis>
        <xyz>1 0 0</xyz>
        <limit>
          <lower>-3.14159</lower>
          <upper>3.14159</upper>
          <effort>25</effort>
          <velocity>1.5</velocity>
        </limit>
        <dynamics>
          <spring_reference>0</spring_reference>
          <spring_stiffness>0</spring_stiffness>
        </dynamics>
      </axis>
    </joint>
    <link name='rf_hip_link'>
      <pose relative_to='rf_hip_joint'>0 0 0 0 -0 0</pose>
      <inertial>
        <pose>0 0 0 0 -0 0</pose>
        <mass>0.25</mass>
        <inertia>
          <ixx>0.000485417</ixx>
          <ixy>0</ixy>
          <ixz>0</ixz>
          <iyy>0.000613417</iyy>
          <iyz>0</iyz>
          <izz>0.000394667</izz>
        </inertia>
      </inertial>
      <collision name='rf_hip_link_collision'>
        <pose>0 0 0 0 -0 0</pose>
        <geometry>
          <mesh>
            <scale>0.001 0.001 0.001</scale>
            <uri>file:///root/ros2_ws/install/champ_description/share/champ_description/meshes/hip.stl</uri>
          </mesh>
        </geometry>
        <surface>
          <contact>
            <ode/>
          </contact>
          <friction>
            <ode/>
          </friction>
        </surface>
      </collision>
      <visual name='rf_hip_link_visual'>
        <pose>0 0 0 0 -0 0</pose>
        <geometry>
          <mesh>
            <scale>0.001 0.001 0.001</scale>
            <uri>file:///root/ros2_ws/install/champ_description/share/champ_description/meshes/hip.stl</uri>
          </mesh>
        </geometry>
        <material>
          <script>
            <name>Gazebo/FlatBlack</name>
            <uri>file://media/materials/scripts/gazebo.material</uri>
          </script>
        </material>
      </visual>
    </link>
    <joint name='rf_upper_leg_joint' type='revolute'>
      <pose relative_to='rf_hip_link'>0 -0.06 0 0 -0 0</pose>
      <parent>rf_hip_link</parent>
      <child>rf_upper_leg_link</child>
      <axis>
        <xyz>0 1 0</xyz>
        <limit>
          <lower>-3.14159</lower>
          <upper>3.14159</upper>
          <effort>25</effort>
          <velocity>1.5</velocity>
        </limit>
        <dynamics>
          <spring_reference>0</spring_reference>
          <spring_stiffness>0</spring_stiffness>
        </dynamics>
      </axis>
    </joint>
    <link name='rf_upper_leg_link'>
      <pose relative_to='rf_upper_leg_joint'>0 0 0 0 -0 0</pose>
      <inertial>
        <pose>0 0 -0.0705 0 -0 0</pose>
        <mass>0.125</mass>
        <inertia>
          <ixx>0.000387398</ixx>
          <ixy>0</ixy>
          <ixz>0</ixz>
          <iyy>0.000404065</iyy>
          <iyz>0</iyz>
          <izz>3.54167e-05</izz>
        </inertia>
      </inertial>
      <collision name='rf_upper_leg_link_collision'>
        <pose>0 0 0 0 -0 0</pose>
        <geometry>
          <mesh>
            <scale>0.001 0.001 0.001</scale>
            <uri>file:///root/ros2_ws/install/champ_description/share/champ_description/meshes/upper_leg_simple.stl</uri>
          </mesh>
        </geometry>
        <surface>
          <contact>
            <ode/>
          </contact>
          <friction>
            <ode/>
          </friction>
        </surface>
      </collision>
      <visual name='rf_upper_leg_link_visual'>
        <pose>0 0 0 0 -0 0</pose>
        <geometry>
          <mesh>
            <scale>0.001 0.001 0.001</scale>
            <uri>file:///root/ros2_ws/install/champ_description/share/champ_description/meshes/upper_leg_simple.stl</uri>
          </mesh>
        </geometry>
        <material>
          <script>
            <name>Gazebo/FlatBlack</name>
            <uri>file://media/materials/scripts/gazebo.material</uri>
          </script>
        </material>
      </visual>
    </link>
    <joint name='rf_lower_leg_joint' type='revolute'>
      <pose relative_to='rf_upper_leg_link'>0 0 -0.141 0 -0 0</pose>
      <parent>rf_upper_leg_link</parent>
      <child>rf_lower_leg_link</child>
      <axis>
        <xyz>0 1 0</xyz>
        <limit>
          <lower>-3.14159</lower>
          <upper>3.14159</upper>
          <effort>25</effort>
          <velocity>1.5</velocity>
        </limit>
        <dynamics>
          <spring_reference>0</spring_reference>
          <spring_stiffness>0</spring_stiffness>
        </dynamics>
      </axis>
    </joint>
    <link name='rf_lower_leg_link'>
      <pose relative_to='rf_lower_leg_joint'>0 0 0 0 -0 0</pose>
      <inertial>
        <pose>0 0 -0.063 0 -0 0</pose>
        <mass>0.125</mass>
        <inertia>
          <ixx>0.000258542</ixx>
          <ixy>0</ixy>
          <ixz>0</ixz>
          <iyy>0.000269344</iyy>
          <iyz>0</iyz>
          <izz>2.08854e-05</izz>
        </inertia>
      </inertial>
      <collision name='rf_lower_leg_link_collision'>
        <pose>0 0 0 0 -0 0</pose>
        <geometry>
          <mesh>
            <scale>0.001 0.001 0.001</scale>
            <uri>file:///root/ros2_ws/install/champ_description/share/champ_description/meshes/lower_leg_simple.stl</uri>
          </mesh>
        </geometry>
        <surface>
          <contact>
            <ode>
              <kp>1e+10</kp>
              <kd>100</kd>
              <min_depth>0.05</min_depth>
            </ode>
          </contact>
          <friction>
            <ode>
              <mu>0.8</mu>
              <mu2>0.8</mu2>
            </ode>
          </friction>
        </surface>
      </collision>
      <visual name='rf_lower_leg_link_visual'>
        <pose>0 0 0 0 -0 0</pose>
        <geometry>
          <mesh>
            <scale>0.001 0.001 0.001</scale>
            <uri>file:///root/ros2_ws/install/champ_description/share/champ_description/meshes/lower_leg_simple.stl</uri>
          </mesh>
        </geometry>
        <material>
          <script>
            <name>Gazebo/FlatBlack</name>
            <uri>file://media/materials/scripts/gazebo.material</uri>
          </script>
        </material>
      </visual>
    </link>
    <joint name='rh_hip_joint' type='revolute'>
      <pose relative_to='base_link'>-0.175 -0.105 0 0 -0 0</pose>
      <parent>base_link</parent>
      <child>rh_hip_link</child>
      <axis>
        <xyz>1 0 0</xyz>
        <limit>
          <lower>-3.14159</lower>
          <upper>3.14159</upper>
          <effort>25</effort>
          <velocity>1.5</velocity>
        </limit>
        <dynamics>
          <spring_reference>0</spring_reference>
          <spring_stiffness>0</spring_stiffness>
        </dynamics>
      </axis>
    </joint>
    <link name='rh_hip_link'>
      <pose relative_to='rh_hip_joint'>0 0 0 0 -0 0</pose>
      <inertial>
        <pose>0 0 0 0 -0 0</pose>
        <mass>0.25</mass>
        <inertia>
          <ixx>0.000485417</ixx>
          <ixy>0</ixy>
          <ixz>0</ixz>
          <iyy>0.000613417</iyy>
          <iyz>0</iyz>
          <izz>0.000394667</izz>
        </inertia>
      </inertial>
      <collision name='rh_hip_link_collision'>
        <pose>0 0 0 0 -0 0</pose>
        <geometry>
          <mesh>
            <scale>0.001 0.001 0.001</scale>
            <uri>file:///root/ros2_ws/install/champ_description/share/champ_description/meshes/hip.stl</uri>
          </mesh>
        </geometry>
        <surface>
          <contact>
            <ode/>
          </contact>
          <friction>
            <ode/>
          </friction>
        </surface>
      </collision>
      <visual name='rh_hip_link_visual'>
        <pose>0 0 0 0 -0 0</pose>
        <geometry>
          <mesh>
            <scale>0.001 0.001 0.001</scale>
            <uri>file:///root/ros2_ws/install/champ_description/share/champ_description/meshes/hip.stl</uri>
          </mesh>
        </geometry>
        <material>
          <script>
            <name>Gazebo/FlatBlack</name>
            <uri>file://media/materials/scripts/gazebo.material</uri>
          </script>
        </material>
      </visual>
    </link>
    <joint name='rh_upper_leg_joint' type='revolute'>
      <pose relative_to='rh_hip_link'>0 -0.06 0 0 -0 0</pose>
      <parent>rh_hip_link</parent>
      <child>rh_upper_leg_link</child>
      <axis>
        <xyz>0 1 0</xyz>
        <limit>
          <lower>-3.14159</lower>
          <upper>3.14159</upper>
          <effort>25</effort>
          <velocity>1.5</velocity>
        </limit>
        <dynamics>
          <spring_reference>0</spring_reference>
          <spring_stiffness>0</spring_stiffness>
        </dynamics>
      </axis>
    </joint>
    <link name='rh_upper_leg_link'>
      <pose relative_to='rh_upper_leg_joint'>0 0 0 0 -0 0</pose>
      <inertial>
        <pose>0 0 -0.0705 0 -0 0</pose>
        <mass>0.125</mass>
        <inertia>
          <ixx>0.000387398</ixx>
          <ixy>0</ixy>
          <ixz>0</ixz>
          <iyy>0.000404065</iyy>
          <iyz>0</iyz>
          <izz>3.54167e-05</izz>
        </inertia>
      </inertial>
      <collision name='rh_upper_leg_link_collision'>
        <pose>0 0 0 0 -0 0</pose>
        <geometry>
          <mesh>
            <scale>0.001 0.001 0.001</scale>
            <uri>file:///root/ros2_ws/install/champ_description/share/champ_description/meshes/upper_leg_simple.stl</uri>
          </mesh>
        </geometry>
        <surface>
          <contact>
            <ode/>
          </contact>
          <friction>
            <ode/>
          </friction>
        </surface>
      </collision>
      <visual name='rh_upper_leg_link_visual'>
        <pose>0 0 0 0 -0 0</pose>
        <geometry>
          <mesh>
            <scale>0.001 0.001 0.001</scale>
            <uri>file:///root/ros2_ws/install/champ_description/share/champ_description/meshes/upper_leg_simple.stl</uri>
          </mesh>
        </geometry>
        <material>
          <script>
            <name>Gazebo/FlatBlack</name>
            <uri>file://media/materials/scripts/gazebo.material</uri>
          </script>
        </material>
      </visual>
    </link>
    <joint name='rh_lower_leg_joint' type='revolute'>
      <pose relative_to='rh_upper_leg_link'>0 0 -0.141 0 -0 0</pose>
      <parent>rh_upper_leg_link</parent>
      <child>rh_lower_leg_link</child>
      <axis>
        <xyz>0 1 0</xyz>
        <limit>
          <lower>-3.14159</lower>
          <upper>3.14159</upper>
          <effort>25</effort>
          <velocity>1.5</velocity>
        </limit>
        <dynamics>
          <spring_reference>0</spring_reference>
          <spring_stiffness>0</spring_stiffness>
        </dynamics>
      </axis>
    </joint>
    <link name='rh_lower_leg_link'>
      <pose relative_to='rh_lower_leg_joint'>0 0 0 0 -0 0</pose>
      <inertial>
        <pose>0 0 -0.063 0 -0 0</pose>
        <mass>0.125</mass>
        <inertia>
          <ixx>0.000258542</ixx>
          <ixy>0</ixy>
          <ixz>0</ixz>
          <iyy>0.000269344</iyy>
          <iyz>0</iyz>
          <izz>2.08854e-05</izz>
        </inertia>
      </inertial>
      <collision name='rh_lower_leg_link_collision'>
        <pose>0 0 0 0 -0 0</pose>
        <geometry>
          <mesh>
            <scale>0.001 0.001 0.001</scale>
            <uri>file:///root/ros2_ws/install/champ_description/share/champ_description/meshes/lower_leg_simple.stl</uri>
          </mesh>
        </geometry>
        <surface>
          <contact>
            <ode>
              <kp>1e+10</kp>
              <kd>100</kd>
              <min_depth>0.05</min_depth>
            </ode>
          </contact>
          <friction>
            <ode>
              <mu>0.8</mu>
              <mu2>0.8</mu2>
            </ode>
          </friction>
        </surface>
      </collision>
      <visual name='rh_lower_leg_link_visual'>
        <pose>0 0 0 0 -0 0</pose>
        <geometry>
          <mesh>
            <scale>0.001 0.001 0.001</scale>
            <uri>file:///root/ros2_ws/install/champ_description/share/champ_description/meshes/lower_leg_simple.stl</uri>
          </mesh>
        </geometry>
        <material>
          <script>
            <name>Gazebo/FlatBlack</name>
            <uri>file://media/materials/scripts/gazebo.material</uri>
          </script>
        </material>
      </visual>
    </link>
    <static>0</static>
  </model>
</sdf>
